Starting test run at Tue 10/29/2024 17:14:22.66 
============================== 
Running Backend Tests... 
------------------------------ 
C:\Program Files\Python311\Lib\site-packages\flask\testing.py:118: DeprecationWarning: The '__version__' attribute is deprecated and will be removed in Werkzeug 3.1. Use feature detection or 'importlib.metadata.version("werkzeug")' instead.
  "HTTP_USER_AGENT": f"werkzeug/{werkzeug.__version__}",
test_keyword_stats (test_api.TestAPI.test_keyword_stats) ... ERROR
test_login (test_api.TestAPI.test_login) ... ERROR

======================================================================
ERROR: test_keyword_stats (test_api.TestAPI.test_keyword_stats)
----------------------------------------------------------------------
Traceback (most recent call last):
  File "C:\Users\hp\AppData\Roaming\Python\Python311\site-packages\sqlalchemy\engine\base.py", line 1967, in _exec_single_context
    self.dialect.do_execute(
  File "C:\Users\hp\AppData\Roaming\Python\Python311\site-packages\sqlalchemy\engine\default.py", line 941, in do_execute
    cursor.execute(statement, parameters)
sqlite3.OperationalError: no such table: hr_user

The above exception was the direct cause of the following exception:

Traceback (most recent call last):
  File "C:\Users\hp\Desktop\Mental Health bot\tests\test_api.py", line 45, in setUp
    db.session.commit()
  File "C:\Users\hp\AppData\Roaming\Python\Python311\site-packages\sqlalchemy\orm\scoping.py", line 597, in commit
    return self._proxied.commit()
           ^^^^^^^^^^^^^^^^^^^^^^
  File "C:\Users\hp\AppData\Roaming\Python\Python311\site-packages\sqlalchemy\orm\session.py", line 2028, in commit
    trans.commit(_to_root=True)
  File "<string>", line 2, in commit
  File "C:\Users\hp\AppData\Roaming\Python\Python311\site-packages\sqlalchemy\orm\state_changes.py", line 139, in _go
    ret_value = fn(self, *arg, **kw)
                ^^^^^^^^^^^^^^^^^^^^
  File "C:\Users\hp\AppData\Roaming\Python\Python311\site-packages\sqlalchemy\orm\session.py", line 1313, in commit
    self._prepare_impl()
  File "<string>", line 2, in _prepare_impl
  File "C:\Users\hp\AppData\Roaming\Python\Python311\site-packages\sqlalchemy\orm\state_changes.py", line 139, in _go
    ret_value = fn(self, *arg, **kw)
                ^^^^^^^^^^^^^^^^^^^^
  File "C:\Users\hp\AppData\Roaming\Python\Python311\site-packages\sqlalchemy\orm\session.py", line 1288, in _prepare_impl
    self.session.flush()
  File "C:\Users\hp\AppData\Roaming\Python\Python311\site-packages\sqlalchemy\orm\session.py", line 4352, in flush
    self._flush(objects)
  File "C:\Users\hp\AppData\Roaming\Python\Python311\site-packages\sqlalchemy\orm\session.py", line 4487, in _flush
    with util.safe_reraise():
  File "C:\Users\hp\AppData\Roaming\Python\Python311\site-packages\sqlalchemy\util\langhelpers.py", line 146, in __exit__
    raise exc_value.with_traceback(exc_tb)
  File "C:\Users\hp\AppData\Roaming\Python\Python311\site-packages\sqlalchemy\orm\session.py", line 4448, in _flush
    flush_context.execute()
  File "C:\Users\hp\AppData\Roaming\Python\Python311\site-packages\sqlalchemy\orm\unitofwork.py", line 466, in execute
    rec.execute(self)
  File "C:\Users\hp\AppData\Roaming\Python\Python311\site-packages\sqlalchemy\orm\unitofwork.py", line 642, in execute
    util.preloaded.orm_persistence.save_obj(
  File "C:\Users\hp\AppData\Roaming\Python\Python311\site-packages\sqlalchemy\orm\persistence.py", line 93, in save_obj
    _emit_insert_statements(
  File "C:\Users\hp\AppData\Roaming\Python\Python311\site-packages\sqlalchemy\orm\persistence.py", line 1233, in _emit_insert_statements
    result = connection.execute(
             ^^^^^^^^^^^^^^^^^^^
  File "C:\Users\hp\AppData\Roaming\Python\Python311\site-packages\sqlalchemy\engine\base.py", line 1418, in execute
    return meth(
           ^^^^^
  File "C:\Users\hp\AppData\Roaming\Python\Python311\site-packages\sqlalchemy\sql\elements.py", line 515, in _execute_on_connection
    return connection._execute_clauseelement(
           ^^^^^^^^^^^^^^^^^^^^^^^^^^^^^^^^^^
  File "C:\Users\hp\AppData\Roaming\Python\Python311\site-packages\sqlalchemy\engine\base.py", line 1640, in _execute_clauseelement
    ret = self._execute_context(
          ^^^^^^^^^^^^^^^^^^^^^^
  File "C:\Users\hp\AppData\Roaming\Python\Python311\site-packages\sqlalchemy\engine\base.py", line 1846, in _execute_context
    return self._exec_single_context(
           ^^^^^^^^^^^^^^^^^^^^^^^^^^
  File "C:\Users\hp\AppData\Roaming\Python\Python311\site-packages\sqlalchemy\engine\base.py", line 1986, in _exec_single_context
    self._handle_dbapi_exception(
  File "C:\Users\hp\AppData\Roaming\Python\Python311\site-packages\sqlalchemy\engine\base.py", line 2355, in _handle_dbapi_exception
    raise sqlalchemy_exception.with_traceback(exc_info[2]) from e
  File "C:\Users\hp\AppData\Roaming\Python\Python311\site-packages\sqlalchemy\engine\base.py", line 1967, in _exec_single_context
    self.dialect.do_execute(
  File "C:\Users\hp\AppData\Roaming\Python\Python311\site-packages\sqlalchemy\engine\default.py", line 941, in do_execute
    cursor.execute(statement, parameters)
sqlalchemy.exc.OperationalError: (sqlite3.OperationalError) no such table: hr_user
[SQL: INSERT INTO hr_user (username, password_hash) VALUES (?, ?)]
[parameters: ('testuser', 'scrypt:32768:8:1$LvomdU8asOWxAOrQ$5af262f7761f64f4441a81dcfdbfc1535c51a722ef8316e4b4da5e877c8d3671be24fa1f0373f5308232b85968db04ede39f33de0e55cbc5d417796c7149181f')]
(Background on this error at: https://sqlalche.me/e/20/e3q8)

======================================================================
ERROR: test_login (test_api.TestAPI.test_login)
----------------------------------------------------------------------
Traceback (most recent call last):
  File "C:\Users\hp\AppData\Roaming\Python\Python311\site-packages\sqlalchemy\engine\base.py", line 1967, in _exec_single_context
    self.dialect.do_execute(
  File "C:\Users\hp\AppData\Roaming\Python\Python311\site-packages\sqlalchemy\engine\default.py", line 941, in do_execute
    cursor.execute(statement, parameters)
sqlite3.OperationalError: no such table: hr_user

The above exception was the direct cause of the following exception:

Traceback (most recent call last):
  File "C:\Users\hp\Desktop\Mental Health bot\tests\test_api.py", line 45, in setUp
    db.session.commit()
  File "C:\Users\hp\AppData\Roaming\Python\Python311\site-packages\sqlalchemy\orm\scoping.py", line 597, in commit
    return self._proxied.commit()
           ^^^^^^^^^^^^^^^^^^^^^^
  File "C:\Users\hp\AppData\Roaming\Python\Python311\site-packages\sqlalchemy\orm\session.py", line 2028, in commit
    trans.commit(_to_root=True)
  File "<string>", line 2, in commit
  File "C:\Users\hp\AppData\Roaming\Python\Python311\site-packages\sqlalchemy\orm\state_changes.py", line 139, in _go
    ret_value = fn(self, *arg, **kw)
                ^^^^^^^^^^^^^^^^^^^^
  File "C:\Users\hp\AppData\Roaming\Python\Python311\site-packages\sqlalchemy\orm\session.py", line 1313, in commit
    self._prepare_impl()
  File "<string>", line 2, in _prepare_impl
  File "C:\Users\hp\AppData\Roaming\Python\Python311\site-packages\sqlalchemy\orm\state_changes.py", line 139, in _go
    ret_value = fn(self, *arg, **kw)
                ^^^^^^^^^^^^^^^^^^^^
  File "C:\Users\hp\AppData\Roaming\Python\Python311\site-packages\sqlalchemy\orm\session.py", line 1288, in _prepare_impl
    self.session.flush()
  File "C:\Users\hp\AppData\Roaming\Python\Python311\site-packages\sqlalchemy\orm\session.py", line 4352, in flush
    self._flush(objects)
  File "C:\Users\hp\AppData\Roaming\Python\Python311\site-packages\sqlalchemy\orm\session.py", line 4487, in _flush
    with util.safe_reraise():
  File "C:\Users\hp\AppData\Roaming\Python\Python311\site-packages\sqlalchemy\util\langhelpers.py", line 146, in __exit__
    raise exc_value.with_traceback(exc_tb)
  File "C:\Users\hp\AppData\Roaming\Python\Python311\site-packages\sqlalchemy\orm\session.py", line 4448, in _flush
    flush_context.execute()
  File "C:\Users\hp\AppData\Roaming\Python\Python311\site-packages\sqlalchemy\orm\unitofwork.py", line 466, in execute
    rec.execute(self)
  File "C:\Users\hp\AppData\Roaming\Python\Python311\site-packages\sqlalchemy\orm\unitofwork.py", line 642, in execute
    util.preloaded.orm_persistence.save_obj(
  File "C:\Users\hp\AppData\Roaming\Python\Python311\site-packages\sqlalchemy\orm\persistence.py", line 93, in save_obj
    _emit_insert_statements(
  File "C:\Users\hp\AppData\Roaming\Python\Python311\site-packages\sqlalchemy\orm\persistence.py", line 1233, in _emit_insert_statements
    result = connection.execute(
             ^^^^^^^^^^^^^^^^^^^
  File "C:\Users\hp\AppData\Roaming\Python\Python311\site-packages\sqlalchemy\engine\base.py", line 1418, in execute
    return meth(
           ^^^^^
  File "C:\Users\hp\AppData\Roaming\Python\Python311\site-packages\sqlalchemy\sql\elements.py", line 515, in _execute_on_connection
    return connection._execute_clauseelement(
           ^^^^^^^^^^^^^^^^^^^^^^^^^^^^^^^^^^
  File "C:\Users\hp\AppData\Roaming\Python\Python311\site-packages\sqlalchemy\engine\base.py", line 1640, in _execute_clauseelement
    ret = self._execute_context(
          ^^^^^^^^^^^^^^^^^^^^^^
  File "C:\Users\hp\AppData\Roaming\Python\Python311\site-packages\sqlalchemy\engine\base.py", line 1846, in _execute_context
    return self._exec_single_context(
           ^^^^^^^^^^^^^^^^^^^^^^^^^^
  File "C:\Users\hp\AppData\Roaming\Python\Python311\site-packages\sqlalchemy\engine\base.py", line 1986, in _exec_single_context
    self._handle_dbapi_exception(
  File "C:\Users\hp\AppData\Roaming\Python\Python311\site-packages\sqlalchemy\engine\base.py", line 2355, in _handle_dbapi_exception
    raise sqlalchemy_exception.with_traceback(exc_info[2]) from e
  File "C:\Users\hp\AppData\Roaming\Python\Python311\site-packages\sqlalchemy\engine\base.py", line 1967, in _exec_single_context
    self.dialect.do_execute(
  File "C:\Users\hp\AppData\Roaming\Python\Python311\site-packages\sqlalchemy\engine\default.py", line 941, in do_execute
    cursor.execute(statement, parameters)
sqlalchemy.exc.OperationalError: (sqlite3.OperationalError) no such table: hr_user
[SQL: INSERT INTO hr_user (username, password_hash) VALUES (?, ?)]
[parameters: ('testuser', 'scrypt:32768:8:1$NcP9VICfCX97FoZj$7b8cd886f2f4416b161f26b2d556762c7c9bd01a90f87a0b209ce1874bda828afd4a628b569fda2a402f94d5582c57880dbf4f0aa5a1c37faf7552505b63279e')]
(Background on this error at: https://sqlalche.me/e/20/e3q8)

----------------------------------------------------------------------
Ran 2 tests in 0.205s

FAILED (errors=2)
Error in setUp: (sqlite3.OperationalError) no such table: hr_user
[SQL: INSERT INTO hr_user (username, password_hash) VALUES (?, ?)]
[parameters: ('testuser', 'scrypt:32768:8:1$LvomdU8asOWxAOrQ$5af262f7761f64f4441a81dcfdbfc1535c51a722ef8316e4b4da5e877c8d3671be24fa1f0373f5308232b85968db04ede39f33de0e55cbc5d417796c7149181f')]
(Background on this error at: https://sqlalche.me/e/20/e3q8)
Error in setUp: (sqlite3.OperationalError) no such table: hr_user
[SQL: INSERT INTO hr_user (username, password_hash) VALUES (?, ?)]
[parameters: ('testuser', 'scrypt:32768:8:1$NcP9VICfCX97FoZj$7b8cd886f2f4416b161f26b2d556762c7c9bd01a90f87a0b209ce1874bda828afd4a628b569fda2a402f94d5582c57880dbf4f0aa5a1c37faf7552505b63279e')]
(Background on this error at: https://sqlalche.me/e/20/e3q8)
 
Running Frontend Tests... 
------------------------------ 
Installing frontend dependencies... 
npm WARN EBADENGINE Unsupported engine {
npm WARN EBADENGINE   package: '@inquirer/core@10.0.1',
npm WARN EBADENGINE   required: { node: '>=18' },
npm WARN EBADENGINE   current: { node: 'v16.20.0', npm: '8.19.4' }
npm WARN EBADENGINE }
npm WARN EBADENGINE Unsupported engine {
npm WARN EBADENGINE   package: '@inquirer/type@3.0.0',
npm WARN EBADENGINE   required: { node: '>=18' },
npm WARN EBADENGINE   current: { node: 'v16.20.0', npm: '8.19.4' }
npm WARN EBADENGINE }
npm WARN EBADENGINE Unsupported engine {
npm WARN EBADENGINE   package: '@inquirer/figures@1.0.7',
npm WARN EBADENGINE   required: { node: '>=18' },
npm WARN EBADENGINE   current: { node: 'v16.20.0', npm: '8.19.4' }
npm WARN EBADENGINE }
npm WARN EBADENGINE Unsupported engine {
npm WARN EBADENGINE   package: '@mswjs/interceptors@0.36.6',
npm WARN EBADENGINE   required: { node: '>=18' },
npm WARN EBADENGINE   current: { node: 'v16.20.0', npm: '8.19.4' }
npm WARN EBADENGINE }
npm WARN EBADENGINE Unsupported engine {
npm WARN EBADENGINE   package: '@testing-library/dom@10.4.0',
npm WARN EBADENGINE   required: { node: '>=18' },
npm WARN EBADENGINE   current: { node: 'v16.20.0', npm: '8.19.4' }
npm WARN EBADENGINE }
npm WARN EBADENGINE Unsupported engine {
npm WARN EBADENGINE   package: '@testing-library/react@16.0.1',
npm WARN EBADENGINE   required: { node: '>=18' },
npm WARN EBADENGINE   current: { node: 'v16.20.0', npm: '8.19.4' }
npm WARN EBADENGINE }
npm WARN EBADENGINE Unsupported engine {
npm WARN EBADENGINE   package: 'msw@2.5.2',
npm WARN EBADENGINE   required: { node: '>=18' },
npm WARN EBADENGINE   current: { node: 'v16.20.0', npm: '8.19.4' }
npm WARN EBADENGINE }
npm WARN EBADENGINE Unsupported engine {
npm WARN EBADENGINE   package: '@inquirer/confirm@5.0.1',
npm WARN EBADENGINE   required: { node: '>=18' },
npm WARN EBADENGINE   current: { node: 'v16.20.0', npm: '8.19.4' }
npm WARN EBADENGINE }
npm WARN EBADENGINE Unsupported engine {
npm WARN EBADENGINE   package: '@inquirer/type@3.0.0',
npm WARN EBADENGINE   required: { node: '>=18' },
npm WARN EBADENGINE   current: { node: 'v16.20.0', npm: '8.19.4' }
npm WARN EBADENGINE }
npm WARN EBADENGINE Unsupported engine {
npm WARN EBADENGINE   package: 'mute-stream@2.0.0',
npm WARN EBADENGINE   required: { node: '^18.17.0 || >=20.5.0' },
npm WARN EBADENGINE   current: { node: 'v16.20.0', npm: '8.19.4' }
npm WARN EBADENGINE }
npm WARN EBADENGINE Unsupported engine {
npm WARN EBADENGINE   package: 'yoctocolors-cjs@2.1.2',
npm WARN EBADENGINE   required: { node: '>=18' },
npm WARN EBADENGINE   current: { node: 'v16.20.0', npm: '8.19.4' }
npm WARN EBADENGINE }

up to date, audited 1487 packages in 4s

274 packages are looking for funding
  run `npm fund` for details

12 vulnerabilities (3 low, 2 moderate, 7 high)

To address issues that do not require attention, run:
  npm audit fix

To address all issues (including breaking changes), run:
  npm audit fix --force

Run `npm audit` for details.
Running tests... 

> frontend@0.1.0 test
> react-scripts test --watchAll=false --verbose

We detected setupFilesAfterEnv in your package.json.

Remove it from Jest configuration, and put the initialization code in src/setupTests.js.
This file will be loaded automatically.

